Workbook

Sheet Planilha1
E4: MPS - AG PECAS
E5: MPS - AG LOCOMOCAO
E6: MPS - AG LAVADOR
E7: MPS - AG LUBRIFICACAO
E8: MPNS - AG BORRACHARIA
E9: MPNS - AG MAU TEMPO
E10: MPS - AG LIBERACAO DE ACESSO
E11: MPS - AG BORRACHARIA
E12: MPS - AG RECURSO/FERRAMENTAL
E13: MPNS - AG AVALIACAO
E14: MPNS - AG LOCOMOCAO
E15: MPS - AG RADIO/DESPACHO/CAMERA
... E25: MPS - AG ABASTECIMENTO

Sheet Planilha2
A1: EXPURGO Mãe | B1: (Vários itens)
A3: Rótulos de Linha | B3: Soma de Expurgo Total
A4: CA1014KS101 | B4: 232.21877
A5: CA1014KS102 | B5: 3269.2511
A6: CA1014KS103 | B6: 190.05834
A7: CA1014KS104 | B7: 238.04251
A8: Total Geral | B8: 3929.5707

Sheet LISTAS_APOIO
B1: Build up | D1: Perfil de perdas | E1: Build Up Corretiva | F1: Build Up Preventia | G1: Expurgo | I1: COD DESPACHO | K1: SISTEMA - HISTÓRICO | L1: PERFIL | N1: EXPURGO - FILHAS | P1: SIM / NÃO | R1: 0 / 1 | T1: TIPO PM | V1: MTBF.PÓS.PM - DATA
B2: Acessórios | D2: ACIDENTE | E2: Acidente operacional | F2: Acidente operacional | G2: SIM | I2: MPS - Hora Manutenção Preventiva Sistemática | K2: INSPEÇÃO | L2: INSPEÇÃO SENSITIVA | N2: MPS - AG PECAS | P2: SIM | R2: 0 | T2: 250 | V2: SEM OCORRENCIA
B3: Acidente operacional | D3: AR CONDICIONADO | E3: Corretivas | F3: Reparo Programado | G3: NÃO | I3: HMC - Hora de Manutenção Corretiva | K3: ELETRICO | L3: ELETRICO | N3: MPS - AG LOCOMOCAO | P3: NÃO | R3: 1 | T3: 500
B4: Corretivas | D4: AUTOMAÇÃO | E4: Acessórios | F4: Acessórios | G4: SIM | I4: MPNS - Hora Manutenção Preventiva não Sistemática | K4: DIRECAO | L4: DIRECAO | N4: MPS - AG LAVADOR | T4: 1000
B5: Inspeção | D5: BACKLOGS | F5: Reparo Programado | G5: NÃO | I5: HAC - Hora Acidente | K5: LOCOMOCAO | L5: LOCOMOÇÃO | N5: MPS - AG LUBRIFICACAO | T5: 1500
B6: Man. Pneus | D6: CAS | E6: Acessórios | F6: Acessórios | G6: SIM | K6: INSPEÇÃO DE PNEUS | L6: INSPEÇÃO DE PNEUS | N6: MPNS - AG BORRACHARIA | T6: 2000
B7: Preventivas | D7: COMBATE INCENDIO | E7: Acessórios | F7: Acessórios | G7: SIM | K7: REVISÃO DE 1000H | L7: REVISÃO PREVENTIVA | N7: MPNS - AG MAU TEMPO | T7: 2500
B8: Reparo Programado | D8: COMUNICACAO | E8: Acessórios | F8: Acessórios | G8: SIM | K8: REVISÃO DE 500H | L8: REVISÃO PREVENTIVA | N8: MPS - AG LIBERACAO DE ACESSO | T8: 3000
B9: Componente (Major e Minor) | D9: COMANDO FINAL | E9: Corretivas | F9: Reparo Programado | G9: NÃO | K9: ERRO DE APROPRIAÇÃO DE CÓDIGO | L9: ERRO DE APROPRIAÇÃO DE CÓDIGO | N9: MPS - AG BORRACHARIA | T9: 3500
D10: DESPACHO | E10: Corretivas | F10: Reparo Programado | G10: NÃO | K10: REVISÃO DE 250H | L10: REVISÃO PREVENTIVA | N10: HMC - AG RECURSO/FERRAMENTAL | T10: 4000
B11: - | D11: DIRECAO | E11: Corretivas | F11: Reparo Programado | G11: NÃO | K11: DESPACHO | L11: DESPACHO | N11: MPNS - AG RECURSO/FERRAMENTAL | T11: 4500
D12: ELETRICO | E12: Corretivas | F12: Reparo Programado | G12: NÃO | K12: ELEVACAO | L12: ELEVAÇÃO | N12: MPS - AG RECURSO/FERRAMENTAL | T12: 5000
D13: ELEVAÇÃO | E13: Corretivas | F13: Reparo Programado | G13: NÃO | K13: SISTEMA AFEX | L13: COMBATE INCENDIO | N13: HMC - AG MAU TEMPO | T13: 5500
D14: ERRO DE APROPRIAÇÃO DE CÓDIGO | E14: Acessórios | F14: Acessórios | G14: SIM | K14: MOTOR DE COMBUSTAO | L14: MOTOR DE COMBUSTÃO | N14: HMC - AG LOCOMOCAO | T14: 6000
D15: ESTRUTURA | E15: Corretivas | F15: Reparo Programado | G15: NÃO | K15: RADIO VOZ | L15: COMUNICACAO | N15: MPNS - AG AVALIACAO | T15: 6500
D16: INSPEÇÃO DE PNEUS | E16: Acessórios | F16: Acessórios | G16: SIM | K16: AR CONDICIONADO | L16: AR CONDICIONADO | N16: MPNS - AG DETONACAO | T16: 7000
D17: INSPEÇÃO SENSITIVA | E17: Inspeção | F17: Inspeção | G17: NÃO | K17: PROPULSAO E RETARDO | L17: PROPULSAO E RETARDO | N17: MPS - AG DETONACAO | T17: 7500
D18: INSPEÇÃO VALE | E18: Acessórios | F18: Acessórios | G18: SIM | K18: SEM INFORMAÇÃO DA OPERAÇÃO | L18: SEM INFORMAÇÃO DA OPERAÇÃO | N18: HMC - AG DETONACAO | T18: 8000
D19: BORRACHARIA | E19: Man. Pneus | F19: Man. Pneus | G19: NÃO | K19: SISTEMA MONIT. DE PNEUS | L19: MONI. PNEUS | N19: HMC - AG LIBERACAO DE ACESSO | T19: 50F
D20: LUBRIFICAÇÃO CENTRALIZADA | E20: Corretivas | F20: Reparo Programado | G20: NÃO | K20: REVISÃO DE 1500H | L20: REVISÃO PREVENTIVA | N20: MPS - AG ATENDIMENTO | T20: 250F
D21: MOTOR DE COMBUSTÃO | E21: Corretivas | F21: Reparo Programado | G21: NÃO | K21: ESTRUTURA | L21: ESTRUTURA | N21: HMC - AG ATENDIMENTO | T21: PM+MIDLIFE
D22: MONI. PNEUS | E22: Acessórios | F22: Acessórios | G22: SIM | K22: SUSPENSAO | L22: SUSPENSÃO | N22: MPS - AG MANUT
D23: PM AUTOMAÇÃO | E23: Acessórios | F23: Acessórios | G23: SIM | K23: PIT STOP | L23: REVISÃO PREVENTIVA | N23: MPNS - AG LOCOMOCAO
D24: PROPULSAO E RETARDO | E24: Corretivas | F24: Reparo Programado | G24: NÃO | K24: REVISÃO DE 2000H | L24: REVISÃO PREVENTIVA | N24: MPS - AG RADIO/DESPACHO/CAMERA
D25: REVISÃO PREVENTIVA | E25: Preventivas | F25: Preventivas | G25: NÃO | K25: REVISÃO DE 2500H | L25: REVISÃO PREVENTIVA | N25: MPNS - AG GARANTIA / ASSIST TECNICA
D26: TKPH | E26: Corretivas | F26: Reparo Programado | G26: NÃO | K26: REVISÃO DE 3000H | L26: REVISÃO PREVENTIVA | N26: MPNS - AG LUBRIFICACAO
D27: SEM INFORMAÇÃO DA OPERAÇÃO | E27: Acessórios | F27: Acessórios | G27: SIM | K27: CAS | L27: CAS | N27: HMC - AG LUBRIFICACAO
D28: SISTEMA ALERTA DE FADIGA | E28: Acessórios | F28: Acessórios | G28: SIM | K28: FRENAGEM | L28: SISTEMA DE FREIO | N28: MPNS - AG LIBERACAO DE ACESSO
D29: SISTEMA DE FREIO | E29: Corretivas | F29: Reparo Programado | G29: NÃO | K29: LUBRIFICACAO CENTRALIZADA | L29: LUBRIFICAÇÃO CENTRALIZADA | N29: MPNS - AG PECAS
D30: SUSPENSÃO | E30: Corretivas | F30: Reparo Programado | G30: NÃO | K30: CFTV | L30: ELETRICO | N30: MPS - AG MAU TEMPO
D31: ARREFECIMENTO | E31: Corretivas | F31: Reparo Programado | G31: NÃO | K31: REVISÃO DE 3500H | L31: REVISÃO PREVENTIVA | N31: HMC - AG PECAS
D32: PRODUTO/CORRETIVA CAT | E32: Produto/Corretiva Cat | G32: NÃO | K32: REVISÃO DE 4000H | L32: REVISÃO PREVENTIVA | N32: HMC - AG BOX
D33: AUTONOMO TRANSPORTE | E33: Acessórios | F33: Acessórios | G33: SIM | K33: SISTEMA ALERTA DE FADIGA | L33: SISTEMA ALERTA DE FADIGA | N33: MPS - AG BOX
D34: KING PIN | E34: Corretivas | F34: Componente (Major e Minor) | G34: NÃO | K34: COMANDO FINAL | L34: COMANDO FINAL | N34: HAC - AG MANUT ACIDENTE
D35: CUBO DE RODA | E35: Corretivas | F35: Componente (Major e Minor) | K35: ACIDENTE | L35: ACIDENTE | N35: HMC - AG LAVADOR
D36: EIXO TRASEIRO | E36: Corretivas | F36: Reparo Programado | G36: NÃO | K36: ARREFECIMENTO | L36: ARREFECIMENTO | N36: HMC - AG APROVACAO
D37: EIXO DIANTEIRO | E37: Corretivas | F37: Reparo Programado | G37: NÃO | K37: AUTONOMO TRANSPORTE | L37: AUTONOMO TRANSPORTE | N37: MPS - AG APROVACAO
D38: MOTOR DE TRAÇÃO | E38: Componente (Major e Minor) | F38: Componente (Major e Minor) | G38: NÃO | L38: MOTOR DE TRAÇÃO | N38: HMC - AG CONDICAO SEGURA
D39: GERADOR | E39: Componente (Major e Minor) | F39: Componente (Major e Minor) | G39: NÃO | L39: GERADOR | N39: MPNS - AG CONDICAO SEGURA
D40: CILINDRO DE ELEVAÇÃO | K40: EIXO TRASEIRO | L40: EIXO TRASEIRO | N40: MPS - AG CONDICAO SEGURA
...

Sheet HISTÓRICO_MANUTENÇÃO
B2: CLASSIFICAÇÃO.PRODUTO | F2: COMPONENTE EM JANELA DE PM | I2: AJUSTE / MANUAL | N2: CLASSIFICAÇÃO - AUTOMÁTICO | S2: EXPURGO - AUTOMÁTICO | W2: Componente e Produto | Y2: BASE DE DADOS - HISTÓRICO DE MANUTENÇÃO VALE
A3: dif. Mês | B3: PRODUTO | C3: DURAÇÃO - PRODUTO MANUAL | D3: CARTA | E3: DURAÇÃO - CARTA MANUAL | F3: COMPONENTE | G3: DURAÇÃO - COMP. MANUAL | H3: Comentários Adicionais (Componentes, produto e Cartas) | I3: Ajuste - Cod. Despacho | J3: AJUSTE - BUILD UP | K3: AJUSTE - SISTEMA | L3: AJUSTE - OCORRENCIA (0 / 1) | M3: AJUSTE - EXPURGO (S/N) | N3: CONT. OCOR. | O3: SISTEMA / PERFIL | P3: CLASSI. | Q3: BUILD UP | R3: Duração Ocorrencia | S3: EXPURGO Mãe | T3: CHECK. EXP. MÃE | U3: EXPURGO Filhas | V3: DUR. EXP. FILHA | W3: DUR. PRODUTO | X3: DUR. COMPONENTE.PM | Y3: Hora Inicio | Z3: Hora Final | AA3: Equipamento | AB3: OM | AC3: Cod Despacho | AD3: Descricao Despacho | AE3: Descricao Manutencao | AF3: Tipo | AG3: Mês | AH3: Comentario | AI3: Sistema2 | AJ3: Conjunto | AK3: Item | AL3: Problema | AM3: Solução | AN3: Setor | AO3: Causa | AP3: Falha
A4: =MONTH(TAB_HISTORICO_MANUT[[#This Row],[Hora Final]])-MONTH(TAB_HISTORICO_MANUT[[#This Row],[Hora Inicio]]) -> 0 | L4: 0 | N4: =IF(TAB_HISTORICO_MANUT[[#This Row],[AJUSTE - OCORRENCIA (0 / 1)]]<>"",TAB_HISTORICO_MANUT[[#This Row],[AJUSTE - OCORRENCIA (0 / 1)]],IF(OR(TAB_HISTORICO_MANUT[[#This Row],[Tipo]]="Filha",TAB_HISTORICO_MANUT[[#This Row],[Tipo]]=""),"",IF(AND(TAB_HISTORICO_MANUT[[#This Row],[Hora Inicio]]=#REF!,TAB_HISTORICO_MANUT[[#This Row],[Equipamento]]=#REF!,TAB_HISTORICO_MANUT[[#This Row],[Descricao Despacho]]=#REF!),0,1))) -> 0 | O4: =IF(TAB_HISTORICO_MANUT[[#This Row],[CONT. OCOR.]]="","",IF(TAB_HISTORICO_MANUT[[#This Row],[AJUSTE - SISTEMA]]<>"",TAB_HISTORICO_MANUT[[#This Row],[AJUSTE - SISTEMA]],IFERROR(VLOOKUP(TAB_HISTORICO_MANUT[[#This Row],[Sistema2]]&TAB_HISTORICO_MANUT[[#This Row],[Conjunto]],AJUSTE_PERFIL[#All],2,0),VLOOKUP(TAB_HISTORICO_MANUT[[#This Row],[Sistema2]],AJUSTE_PERFIL[],2,0)))) -> ESTRUTURA | P4: =IF(TAB_HISTORICO_MANUT[[#This Row],[CONT. OCOR.]]="","",IF(TAB_HISTORICO_MANUT[[#This Row],[Ajuste - Cod. Despacho]]="",TAB_HISTORICO_MANUT[[#This Row],[Descricao Despacho]],TAB_HISTORICO_MANUT[[#This Row],[Ajuste - Cod. Despacho]])) -> HAC - Hora Acidente | Q4: =IF(TAB_HISTORICO_MANUT[[#This Row],[CONT. OCOR.]]="","",IF(TAB_HISTORICO_MANUT[[#This Row],[AJUSTE - BUILD UP]]<>"",TAB_HISTORICO_MANUT[[#This Row],[AJUSTE - BUILD UP]],IF(TAB_HISTORICO_MANUT[[#This Row],[Descricao Despacho]]=LISTAS_APOIO!$I$5,LISTAS_APOIO!$B$3,IF(OR(TAB_HISTORICO_MANUT[[#This Row],[Descricao Despacho]]=LISTAS_APOIO!$I$3,TAB_HISTORICO_MANUT[[#This Row],[Descricao Despacho]]=LISTAS_APOIO!$I$5),VLOOKUP(TAB_HISTORICO_MANUT[[#This Row],[SISTEMA / PERFIL]],APOIO_EXPURGO_BUILD.UP[[Perfil de perdas]:[Build Up Preventia]],2,0),VLOOKUP(TAB_HISTORICO_MANUT[[#This Row],[SISTEMA / PERFIL]],APOIO_EXPURGO_BUILD.UP[[Perfil de perdas]:[Build Up Preventia]],3,0))))) -> Acidente operacional | R4: =IF($Q4="","",(TAB_HISTORICO_MANUT[[#This Row],[Hora Final]]-TAB_HISTORICO_MANUT[[#This Row],[Hora Inicio]])*24) -> 37.801389 | S4: =IF(TAB_HISTORICO_MANUT[[#This Row],[Tipo]]<>"Mãe","",IF(TAB_HISTORICO_MANUT[[#This Row],[AJUSTE - EXPURGO (S/N)]]<>"",TAB_HISTORICO_MANUT[[#This Row],[AJUSTE - EXPURGO (S/N)]],IF(TAB_HISTORICO_MANUT[[#This Row],[Descricao Despacho]]=LISTAS_APOIO!$I$5,"SIM",IF(ISERROR(VLOOKUP(TAB_HISTORICO_MANUT[[#This Row],[Descricao Manutencao]],EXPURGO_FILHAS[EXPURGO - FILHAS],1,0)),(_xlfn.XLOOKUP(TAB_HISTORICO_MANUT[[#This Row],[SISTEMA / PERFIL]],APOIO_EXPURGO_BUILD.UP[Perfil de perdas],APOIO_EXPURGO_BUILD.UP[Expurgo],"ADICIONAR CÓDIGO",0,1)),"SIM")))) -> SIM | T4: =IF(AND(TAB_HISTORICO_MANUT[[#This Row],[EXPURGO Mãe]]="SIM",TAB_HISTORICO_MANUT[[#This Row],[Tipo]]="MÃE"),"EXP.MAE",IF(TAB_HISTORICO_MANUT[[#This Row],[EXPURGO Mãe]]="NÃO","NÃO EXP.MAE",#REF!)) -> EXP.MAE | U4: =IF(TAB_HISTORICO_MANUT[[#This Row],[CHECK. EXP. MÃE]]="EXP.MAE","NÃO",IF(TAB_HISTORICO_MANUT[[#This Row],[Tipo]]="Filha",IF(TAB_HISTORICO_MANUT[[#This Row],[AJUSTE - EXPURGO (S/N)]]="",(IF(ISERROR(VLOOKUP(TAB_HISTORICO_MANUT[[#This Row],[Descricao Manutencao]],EXPURGO_FILHAS[EXPURGO - FILHAS],1,0)),"NÃO","SIM")),TAB_HISTORICO_MANUT[[#This Row],[AJUSTE - EXPURGO (S/N)]]),"NÃO")) -> NÃO | V4: =IF(TAB_HISTORICO_MANUT[[#This Row],[EXPURGO Filhas]]="SIM",MAX(TAB_HISTORICO_MANUT[[#This Row],[Hora Final]]-TAB_HISTORICO_MANUT[[#This Row],[Hora Inicio]],0),0) -> 0 | W4: =IF(AND((TAB_HISTORICO_MANUT[[#This Row],[DURAÇÃO - PRODUTO MANUAL]]+TAB_HISTORICO_MANUT[[#This Row],[DURAÇÃO - CARTA MANUAL]])=0,OR(TAB_HISTORICO_MANUT[[#This Row],[PRODUTO]]="SIM",TAB_HISTORICO_MANUT[[#This Row],[CARTA]]="SIM")),TAB_HISTORICO_MANUT[[#This Row],[Duração Ocorrencia]],TAB_HISTORICO_MANUT[[#This Row],[DURAÇÃO - PRODUTO MANUAL]]+TAB_HISTORICO_MANUT[[#This Row],[DURAÇÃO - CARTA MANUAL]]) -> 0 | X4: =IF(AND(TAB_HISTORICO_MANUT[[#This Row],[COMPONENTE]]="SIM",TAB_HISTORICO_MANUT[[#This Row],[DURAÇÃO - COMP. MANUAL]]=""),TAB_HISTORICO_MANUT[[#This Row],[Duração Ocorrencia]],TAB_HISTORICO_MANUT[[#This Row],[DURAÇÃO - COMP. MANUAL]]) -> 0 | Y4: 46023 | Z4: 46024.575 | AA4: CA1014KS101 | AC4: 1090 | AD4: HAC - Hora Acidente | AE4: HAC - EXEC MANUT ACIDENTE | AF4: Mãe | AG4: =IF(TAB_HISTORICO_MANUT[[#This Row],[Hora Inicio]]="","",MONTH(TAB_HISTORICO_MANUT[[#This Row],[Hora Inicio]])) -> 1 | AH4: AVARIA NO TANQUE DE COMBUSTIVEL - 202506870735 | AI4: ESTRUTURA | AJ4: TANQUE DE COMBUSTIVEL | AK4: TANQUE | AL4: ACIDENTE | AM4: REPARAR
A5: =MONTH(TAB_HISTORICO_MANUT[[#This Row],[Hora Final]])-MONTH(TAB_HISTORICO_MANUT[[#This Row],[Hora Inicio]]) -> 0 | N5: =IF(TAB_HISTORICO_MANUT[[#This Row],[AJUSTE - OCORRENCIA (0 / 1)]]<>"",TAB_HISTORICO_MANUT[[#This Row],[AJUSTE - OCORRENCIA (0 / 1)]],IF(OR(TAB_HISTORICO_MANUT[[#This Row],[Tipo]]="Filha",TAB_HISTORICO_MANUT[[#This Row],[Tipo]]=""),"",IF(AND(TAB_HISTORICO_MANUT[[#This Row],[Hora Inicio]]=Z4,TAB_HISTORICO_MANUT[[#This Row],[Equipamento]]=AA4,TAB_HISTORICO_MANUT[[#This Row],[Descricao Despacho]]=AD4),0,1))) -> 1 | O5: =IF(TAB_HISTORICO_MANUT[[#This Row],[CONT. OCOR.]]="","",IF(TAB_HISTORICO_MANUT[[#This Row],[AJUSTE - SISTEMA]]<>"",TAB_HISTORICO_MANUT[[#This Row],[AJUSTE - SISTEMA]],IFERROR(VLOOKUP(TAB_HISTORICO_MANUT[[#This Row],[Sistema2]]&TAB_HISTORICO_MANUT[[#This Row],[Conjunto]],AJUSTE_PERFIL[#All],2,0),VLOOKUP(TAB_HISTORICO_MANUT[[#This Row],[Sistema2]],AJUSTE_PERFIL[],2,0)))) -> LOCOMOÇÃO | P5: =IF(TAB_HISTORICO_MANUT[[#This Row],[CONT. OCOR.]]="","",IF(TAB_HISTORICO_MANUT[[#This Row],[Ajuste - Cod. Despacho]]="",TAB_HISTORICO_MANUT[[#This Row],[Descricao Despacho]],TAB_HISTORICO_MANUT[[#This Row],[Ajuste - Cod. Despacho]])) -> MPNS - Hora Manutenção Preventiva não Sistemática | Q5: =IF(TAB_HISTORICO_MANUT[[#This Row],[CONT. OCOR.]]="","",IF(TAB_HISTORICO_MANUT[[#This Row],[AJUSTE - BUILD UP]]<>"",TAB_HISTORICO_MANUT[[#This Row],[AJUSTE - BUILD UP]],IF(TAB_HISTORICO_MANUT[[#This Row],[Descricao Despacho]]=LISTAS_APOIO!$I$5,LISTAS_APOIO!$B$3,IF(OR(TAB_HISTORICO_MANUT[[#This Row],[Descricao Despacho]]=LISTAS_APOIO!$I$3,TAB_HISTORICO_MANUT[[#This Row],[Descricao Despacho]]=LISTAS_APOIO!$I$5),VLOOKUP(TAB_HISTORICO_MANUT[[#This Row],[SISTEMA / PERFIL]],APOIO_EXPURGO_BUILD.UP[[Perfil de perdas]:[Build Up Preventia]],2,0),VLOOKUP(TAB_HISTORICO_MANUT[[#This Row],[SISTEMA / PERFIL]],APOIO_EXPURGO_BUILD.UP[[Perfil de perdas]:[Build Up Preventia]],3,0))))) -> Man. Pneus | R5: =IF($Q5="","",(TAB_HISTORICO_MANUT[[#This Row],[Hora Final]]-TAB_HISTORICO_MANUT[[#This Row],[Hora Inicio]])*24) -> 1.1855556 | S5: =IF(TAB_HISTORICO_MANUT[[#This Row],[Tipo]]<>"Mãe","",IF(TAB_HISTORICO_MANUT[[#This Row],[AJUSTE - EXPURGO (S/N)]]<>"",TAB_HISTORICO_MANUT[[#This Row],[AJUSTE - EXPURGO (S/N)]],IF(TAB_HISTORICO_MANUT[[#This Row],[Descricao Despacho]]=LISTAS_APOIO!$I$5,"SIM",IF(ISERROR(VLOOKUP(TAB_HISTORICO_MANUT[[#This Row],[Descricao Manutencao]],EXPURGO_FILHAS[EXPURGO - FILHAS],1,0)),(_xlfn.XLOOKUP(TAB_HISTORICO_MANUT[[#This Row],[SISTEMA / PERFIL]],APOIO_EXPURGO_BUILD.UP[Perfil de perdas],APOIO_EXPURGO_BUILD.UP[Expurgo],"ADICIONAR CÓDIGO",0,1)),"SIM")))) -> NÃO | T5: =IF(AND(TAB_HISTORICO_MANUT[[#This Row],[EXPURGO Mãe]]="SIM",TAB_HISTORICO_MANUT[[#This Row],[Tipo]]="MÃE"),"EXP.MAE",IF(TAB_HISTORICO_MANUT[[#This Row],[EXPURGO Mãe]]="NÃO","NÃO EXP.MAE",T4)) -> NÃO EXP.MAE | U5: =IF(TAB_HISTORICO_MANUT[[#This Row],[CHECK. EXP. MÃE]]="EXP.MAE","NÃO",IF(TAB_HISTORICO_MANUT[[#This Row],[Tipo]]="Filha",IF(TAB_HISTORICO_MANUT[[#This Row],[AJUSTE - EXPURGO (S/N)]]="",(IF(ISERROR(VLOOKUP(TAB_HISTORICO_MANUT[[#This Row],[Descricao Manutencao]],EXPURGO_FILHAS[EXPURGO - FILHAS],1,0)),"NÃO","SIM")),TAB_HISTORICO_MANUT[[#This Row],[AJUSTE - EXPURGO (S/N)]]),"NÃO")) -> NÃO | V5: =IF(TAB_HISTORICO_MANUT[[#This Row],[EXPURGO Filhas]]="SIM",MAX(TAB_HISTORICO_MANUT[[#This Row],[Hora Final]]-TAB_HISTORICO_MANUT[[#This Row],[Hora Inicio]],0),0) -> 0 | W5: =IF(AND((TAB_HISTORICO_MANUT[[#This Row],[DURAÇÃO - PRODUTO MANUAL]]+TAB_HISTORICO_MANUT[[#This Row],[DURAÇÃO - CARTA MANUAL]])=0,OR(TAB_HISTORICO_MANUT[[#This Row],[PRODUTO]]="SIM",TAB_HISTORICO_MANUT[[#This Row],[CARTA]]="SIM")),TAB_HISTORICO_MANUT[[#This Row],[Duração Ocorrencia]],TAB_HISTORICO_MANUT[[#This Row],[DURAÇÃO - PRODUTO MANUAL]]+TAB_HISTORICO_MANUT[[#This Row],[DURAÇÃO - CARTA MANUAL]]) -> 0 | X5: =IF(AND(TAB_HISTORICO_MANUT[[#This Row],[COMPONENTE]]="SIM",TAB_HISTORICO_MANUT[[#This Row],[DURAÇÃO - COMP. MANUAL]]=""),TAB_HISTORICO_MANUT[[#This Row],[Duração Ocorrencia]],TAB_HISTORICO_MANUT[[#This Row],[DURAÇÃO - COMP. MANUAL]]) -> 0 | Y5: 46025.392 | Z5: 46025.441 | AA5: CA1014KS101 | AC5: 8010 | AD5: MPNS - Hora Manutenção Preventiva não Sistemática | AE5: MPNS - EXEC BORRACHARIA | AF5: Mãe | AG5: =IF(TAB_HISTORICO_MANUT[[#This Row],[Hora Inicio]]="","",MONTH(TAB_HISTORICO_MANUT[[#This Row],[Hora Inicio]])) -> 1 | AI5: LOCOMOCAO
A6: =MONTH(TAB_HISTORICO_MANUT[[#This Row],[Hora Final]])-MONTH(TAB_HISTORICO_MANUT[[#This Row],[Hora Inicio]]) -> 0 | M6: SIM | N6: =IF(TAB_HISTORICO_MANUT[[#This Row],[AJUSTE - OCORRENCIA (0 / 1)]]<>"",TAB_HISTORICO_MANUT[[#This Row],[AJUSTE - OCORRENCIA (0 / 1)]],IF(OR(TAB_HISTORICO_MANUT[[#This Row],[Tipo]]="Filha",TAB_HISTORICO_MANUT[[#This Row],[Tipo]]=""),"",IF(AND(TAB_HISTORICO_MANUT[[#This Row],[Hora Inicio]]=Z5,TAB_HISTORICO_MANUT[[#This Row],[Equipamento]]=AA5,TAB_HISTORICO_MANUT[[#This Row],[Descricao Despacho]]=AD5),0,1))) | O6: =IF(TAB_HISTORICO_MANUT[[#This Row],[CONT. OCOR.]]="","",IF(TAB_HISTORICO_MANUT[[#This Row],[AJUSTE - SISTEMA]]<>"",TAB_HISTORICO_MANUT[[#This Row],[AJUSTE - SISTEMA]],IFERROR(VLOOKUP(TAB_HISTORICO_MANUT[[#This Row],[Sistema2]]&TAB_HISTORICO_MANUT[[#This Row],[Conjunto]],AJUSTE_PERFIL[#All],2,0),VLOOKUP(TAB_HISTORICO_MANUT[[#This Row],[Sistema2]],AJUSTE_PERFIL[],2,0)))) | P6: =IF(TAB_HISTORICO_MANUT[[#This Row],[CONT. OCOR.]]="","",IF(TAB_HISTORICO_MANUT[[#This Row],[Ajuste - Cod. Despacho]]="",TAB_HISTORICO_MANUT[[#This Row],[Descricao Despacho]],TAB_HISTORICO_MANUT[[#This Row],[Ajuste - Cod. Despacho]])) | Q6: =IF(TAB_HISTORICO_MANUT[[#This Row],[CONT. OCOR.]]="","",IF(TAB_HISTORICO_MANUT[[#This Row],[AJUSTE - BUILD UP]]<>"",TAB_HISTORICO_MANUT[[#This Row],[AJUSTE - BUILD UP]],IF(TAB_HISTORICO_MANUT[[#This Row],[Descricao Despacho]]=LISTAS_APOIO!$I$5,LISTAS_APOIO!$B$3,IF(OR(TAB_HISTORICO_MANUT[[#This Row],[Descricao Despacho]]=LISTAS_APOIO!$I$3,TAB_HISTORICO_MANUT[[#This Row],[Descricao Despacho]]=LISTAS_APOIO!$I$5),VLOOKUP(TAB_HISTORICO_MANUT[[#This Row],[SISTEMA / PERFIL]],APOIO_EXPURGO_BUILD.UP[[Perfil de perdas]:[Build Up Preventia]],2,0),VLOOKUP(TAB_HISTORICO_MANUT[[#This Row],[SISTEMA / PERFIL]],APOIO_EXPURGO_BUILD.UP[[Perfil de perdas]:[Build Up Preventia]],3,0))))) | R6: =IF($Q6="","",(TAB_HISTORICO_MANUT[[#This Row],[Hora Final]]-TAB_HISTORICO_MANUT[[#This Row],[Hora Inicio]])*24) | S6: =IF(TAB_HISTORICO_MANUT[[#This Row],[Tipo]]<>"Mãe","",IF(TAB_HISTORICO_MANUT[[#This Row],[AJUSTE - EXPURGO (S/N)]]<>"",TAB_HISTORICO_MANUT[[#This Row],[AJUSTE - EXPURGO (S/N)]],IF(TAB_HISTORICO_MANUT[[#This Row],[Descricao Despacho]]=LISTAS_APOIO!$I$5,"SIM",IF(ISERROR(VLOOKUP(TAB_HISTORICO_MANUT[[#This Row],[Descricao Manutencao]],EXPURGO_FILHAS[EXPURGO - FILHAS],1,0)),(_xlfn.XLOOKUP(TAB_HISTORICO_MANUT[[#This Row],[SISTEMA / PERFIL]],APOIO_EXPURGO_BUILD.UP[Perfil de perdas],APOIO_EXPURGO_BUILD.UP[Expurgo],"ADICIONAR CÓDIGO",0,1)),"SIM")))) | T6: =IF(AND(TAB_HISTORICO_MANUT[[#This Row],[EXPURGO Mãe]]="SIM",TAB_HISTORICO_MANUT[[#This Row],[Tipo]]="MÃE"),"EXP.MAE",IF(TAB_HISTORICO_MANUT[[#This Row],[EXPURGO Mãe]]="NÃO","NÃO EXP.MAE",T5)) -> NÃO EXP.MAE | U6: =IF(TAB_HISTORICO_MANUT[[#This Row],[CHECK. EXP. MÃE]]="EXP.MAE","NÃO",IF(TAB_HISTORICO_MANUT[[#This Row],[Tipo]]="Filha",IF(TAB_HISTORICO_MANUT[[#This Row],[AJUSTE - EXPURGO (S/N)]]="",(IF(ISERROR(VLOOKUP(TAB_HISTORICO_MANUT[[#This Row],[Descricao Manutencao]],EXPURGO_FILHAS[EXPURGO - FILHAS],1,0)),"NÃO","SIM")),TAB_HISTORICO_MANUT[[#This Row],[AJUSTE - EXPURGO (S/N)]]),"NÃO")) -> SIM | V6: =IF(TAB_HISTORICO_MANUT[[#This Row],[EXPURGO Filhas]]="SIM",MAX(TAB_HISTORICO_MANUT[[#This Row],[Hora Final]]-TAB_HISTORICO_MANUT[[#This Row],[Hora Inicio]],0),0) -> 0.039666713 | W6: =IF(AND((TAB_HISTORICO_MANUT[[#This Row],[DURAÇÃO - PRODUTO MANUAL]]+TAB_HISTORICO_MANUT[[#This Row],[DURAÇÃO - CARTA MANUAL]])=0,OR(TAB_HISTORICO_MANUT[[#This Row],[PRODUTO]]="SIM",TAB_HISTORICO_MANUT[[#This Row],[CARTA]]="SIM")),TAB_HISTORICO_MANUT[[#This Row],[Duração Ocorrencia]],TAB_HISTORICO_MANUT[[#This Row],[DURAÇÃO - PRODUTO MANUAL]]+TAB_HISTORICO_MANUT[[#This Row],[DURAÇÃO - CARTA MANUAL]]) -> 0 | X6: =IF(AND(TAB_HISTORICO_MANUT[[#This Row],[COMPONENTE]]="SIM",TAB_HISTORICO_MANUT[[#This Row],[DURAÇÃO - COMP. MANUAL]]=""),TAB_HISTORICO_MANUT[[#This Row],[Duração Ocorrencia]],TAB_HISTORICO_MANUT[[#This Row],[DURAÇÃO - COMP. MANUAL]]) -> 0 | Y6: 46025.401 | Z6: 46025.441 | AA6: CA1014KS101 | AC6: 8010 | AD6: MPNS - Hora Manutenção Preventiva não Sistemática | AE6: MPNS - EXEC BORRACHARIA | AF6: Filha | AG6: =IF(TAB_HISTORICO_MANUT[[#This Row],[Hora Inicio]]="","",MONTH(TAB_HISTORICO_MANUT[[#This Row],[Hora Inicio]])) -> 1 | AI6: LOCOMOCAO
A7: =MONTH(TAB_HISTORICO_MANUT[[#This Row],[Hora Final]])-MONTH(TAB_HISTORICO_MANUT[[#This Row],[Hora Inicio]]) -> 0 | N7: =IF(TAB_HISTORICO_MANUT[[#This Row],[AJUSTE - OCORRENCIA (0 / 1)]]<>"",TAB_HISTORICO_MANUT[[#This Row],[AJUSTE - OCORRENCIA (0 / 1)]],IF(OR(TAB_HISTORICO_MANUT[[#This Row],[Tipo]]="Filha",TAB_HISTORICO_MANUT[[#This Row],[Tipo]]=""),"",IF(AND(TAB_HISTORICO_MANUT[[#This Row],[Hora Inicio]]=Z6,TAB_HISTORICO_MANUT[[#This Row],[Equipamento]]=AA6,TAB_HISTORICO_MANUT[[#This Row],[Descricao Despacho]]=AD6),0,1))) -> 1 | O7: =IF(TAB_HISTORICO_MANUT[[#This Row],[CONT. OCOR.]]="","",IF(TAB_HISTORICO_MANUT[[#This Row],[AJUSTE - SISTEMA]]<>"",TAB_HISTORICO_MANUT[[#This Row],[AJUSTE - SISTEMA]],IFERROR(VLOOKUP(TAB_HISTORICO_MANUT[[#This Row],[Sistema2]]&TAB_HISTORICO_MANUT[[#This Row],[Conjunto]],AJUSTE_PERFIL[#All],2,0),VLOOKUP(TAB_HISTORICO_MANUT[[#This Row],[Sistema2]],AJUSTE_PERFIL[],2,0)))) -> ELETRICO | P7: =IF(TAB_HISTORICO_MANUT[[#This Row],[CONT. OCOR.]]="","",IF(TAB_HISTORICO_MANUT[[#This Row],[Ajuste - Cod. Despacho]]="",TAB_HISTORICO_MANUT[[#This Row],[Descricao Despacho]],TAB_HISTORICO_MANUT[[#This Row],[Ajuste - Cod. Despacho]])) -> HMC - Hora de Manutenção Corretiva | Q7: =IF(TAB_HISTORICO_MANUT[[#This Row],[CONT. OCOR.]]="","",IF(TAB_HISTORICO_MANUT[[#This Row],[AJUSTE - BUILD UP]]<>"",TAB_HISTORICO_MANUT[[#This Row],[AJUSTE - BUILD UP]],IF(TAB_HISTORICO_MANUT[[#This Row],[Descricao Despacho]]=LISTAS_APOIO!$I$5,LISTAS_APOIO!$B$3,IF(OR(TAB_HISTORICO_MANUT[[#This Row],[Descricao Despacho]]=LISTAS_APOIO!$I$3,TAB_HISTORICO_MANUT[[#This Row],[Descricao Despacho]]=LISTAS_APOIO!$I$5),VLOOKUP(TAB_HISTORICO_MANUT[[#This Row],[SISTEMA / PERFIL]],APOIO_EXPURGO_BUILD.UP[[Perfil de perdas]:[Build Up Preventia]],2,0),VLOOKUP(TAB_HISTORICO_MANUT[[#This Row],[SISTEMA / PERFIL]],APOIO_EXPURGO_BUILD.UP[[Perfil de perdas]:[Build Up Preventia]],3,0))))) -> Corretivas | R7: =IF($Q7="","",(TAB_HISTORICO_MANUT[[#This Row],[Hora Final]]-TAB_HISTORICO_MANUT[[#This Row],[Hora Inicio]])*24) -> 4.3983333 | S7: =IF(TAB_HISTORICO_MANUT[[#This Row],[Tipo]]<>"Mãe","",IF(TAB_HISTORICO_MANUT[[#This Row],[AJUSTE - EXPURGO (S/N)]]<>"",TAB_HISTORICO_MANUT[[#This Row],[AJUSTE - EXPURGO (S/N)]],IF(TAB_HISTORICO_MANUT[[#This Row],[Descricao Despacho]]=LISTAS_APOIO!$I$5,"SIM",IF(ISERROR(VLOOKUP(TAB_HISTORICO_MANUT[[#This Row],[Descricao Manutencao]],EXPURGO_FILHAS[EXPURGO - FILHAS],1,0)),(_xlfn.XLOOKUP(TAB_HISTORICO_MANUT[[#This Row],[SISTEMA / PERFIL]],APOIO_EXPURGO_BUILD.UP[Perfil de perdas],APOIO_EXPURGO_BUILD.UP[Expurgo],"ADICIONAR CÓDIGO",0,1)),"SIM")))) -> NÃO | T7: =IF(AND(TAB_HISTORICO_MANUT[[#This Row],[EXPURGO Mãe]]="SIM",TAB_HISTORICO_MANUT[[#This Row],[Tipo]]="MÃE"),"EXP.MAE",IF(TAB_HISTORICO_MANUT[[#This Row],[EXPURGO Mãe]]="NÃO","NÃO EXP.MAE",T6)) -> NÃO EXP.MAE | U7: =IF(TAB_HISTORICO_MANUT[[#This Row],[CHECK. EXP. MÃE]]="EXP.MAE","NÃO",IF(TAB_HISTORICO_MANUT[[#This Row],[Tipo]]="Filha",IF(TAB_HISTORICO_MANUT[[#This Row],[AJUSTE - EXPURGO (S/N)]]="",(IF(ISERROR(VLOOKUP(TAB_HISTORICO_MANUT[[#This Row],[Descricao Manutencao]],EXPURGO_FILHAS[EXPURGO - FILHAS],1,0)),"NÃO","SIM")),TAB_HISTORICO_MANUT[[#This Row],[AJUSTE - EXPURGO (S/N)]]),"NÃO")) -> NÃO | V7: =IF(TAB_HISTORICO_MANUT[[#This Row],[EXPURGO Filhas]]="SIM",MAX(TAB_HISTORICO_MANUT[[#This Row],[Hora Final]]-TAB_HISTORICO_MANUT[[#This Row],[Hora Inicio]],0),0) -> 0 | W7: =IF(AND((TAB_HISTORICO_MANUT[[#This Row],[DURAÇÃO - PRODUTO MANUAL]]+TAB_HISTORICO_MANUT[[#This Row],[DURAÇÃO - CARTA MANUAL]])=0,OR(TAB_HISTORICO_MANUT[[#This Row],[PRODUTO]]="SIM",TAB_HISTORICO_MANUT[[#This Row],[CARTA]]="SIM")),TAB_HISTORICO_MANUT[[#This Row],[Duração Ocorrencia]],TAB_HISTORICO_MANUT[[#This Row],[DURAÇÃO - PRODUTO MANUAL]]+TAB_HISTORICO_MANUT[[#This Row],[DURAÇÃO - CARTA MANUAL]]) -> 0 | X7: =IF(AND(TAB_HISTORICO_MANUT[[#This Row],[COMPONENTE]]="SIM",TAB_HISTORICO_MANUT[[#This Row],[DURAÇÃO - COMP. MANUAL]]=""),TAB_HISTORICO_MANUT[[#This Row],[Duração Ocorrencia]],TAB_HISTORICO_MANUT[[#This Row],[DURAÇÃO - COMP. MANUAL]]) -> 0 | Y7: 46025.486 | Z7: 46025.669 | AA7: CA1014KS101 | AB7: 000000000000 | AC7: 9000 | AD7: HMC - Hora de Manutenção Corretiva | AE7: HMC - EXEC MANUT | AF7: Mãe | AG7: =IF(TAB_HISTORICO_MANUT[[#This Row],[Hora Inicio]]="","",MONTH(TAB_HISTORICO_MANUT[[#This Row],[Hora Inicio]])) -> 1 | AH7: FALHA NO FREIO RETARDO - SUBSTITUÍDO O SENSOR DE LIBERAÇÃO DO FREIO TRASEIRO LD | AI7: ELETRICO | AJ7: FRENAGEM | AK7: SENSOR DE LIBERACAO | AL7: AVARIA | AM7: SUBSTITUIR | AN7: Elétrica | AO7: Propulsao Retardo - Controle Operacao | AP7: Sensor Pres. Atmosf-Queima
A8: =MONTH(TAB_HISTORICO_MANUT[[#This Row],[Hora Final]])-MONTH(TAB_HISTORICO_MANUT[[#This Row],[Hora Inicio]]) -> 0 | N8: =IF(TAB_HISTORICO_MANUT[[#This Row],[AJUSTE - OCORRENCIA (0 / 1)]]<>"",TAB_HISTORICO_MANUT[[#This Row],[AJUSTE - OCORRENCIA (0 / 1)]],IF(OR(TAB_HISTORICO_MANUT[[#This Row],[Tipo]]="Filha",TAB_HISTORICO_MANUT[[#This Row],[Tipo]]=""),"",IF(AND(TAB_HISTORICO_MANUT[[#This Row],[Hora Inicio]]=Z7,TAB_HISTORICO_MANUT[[#This Row],[Equipamento]]=AA7,TAB_HISTORICO_MANUT[[#This Row],[Descricao Despacho]]=AD7),0,1))) -> 1 | O8: =IF(TAB_HISTORICO_MANUT[[#This Row],[CONT. OCOR.]]="","",IF(TAB_HISTORICO_MANUT[[#This Row],[AJUSTE - SISTEMA]]<>"",TAB_HISTORICO_MANUT[[#This Row],[AJUSTE - SISTEMA]],IFERROR(VLOOKUP(TAB_HISTORICO_MANUT[[#This Row],[Sistema2]]&TAB_HISTORICO_MANUT[[#This Row],[Conjunto]],AJUSTE_PERFIL[#All],2,0),VLOOKUP(TAB_HISTORICO_MANUT[[#This Row],[Sistema2]],AJUSTE_PERFIL[],2,0)))) -> LOCOMOÇÃO | P8: =IF(TAB_HISTORICO_MANUT[[#This Row],[CONT. OCOR.]]="","",IF(TAB_HISTORICO_MANUT[[#This Row],[Ajuste - Cod. Despacho]]="",TAB_HISTORICO_MANUT[[#This Row],[Descricao Despacho]],TAB_HISTORICO_MANUT[[#This Row],[Ajuste - Cod. Despacho]])) -> HMC - Hora de Manutenção Corretiva | Q8: =IF(TAB_HISTORICO_MANUT[[#This Row],[CONT. OCOR.]]="","",IF(TAB_HISTORICO_MANUT[[#This Row],[AJUSTE - BUILD UP]]<>"",TAB_HISTORICO_MANUT[[#This Row],[AJUSTE - BUILD UP]],IF(TAB_HISTORICO_MANUT[[#This Row],[Descricao Despacho]]=LISTAS_APOIO!$I$5,LISTAS_APOIO!$B$3,IF(OR(TAB_HISTORICO_MANUT[[#This Row],[Descricao Despacho]]=LISTAS_APOIO!$I$3,TAB_HISTORICO_MANUT[[#This Row],[Descricao Despacho]]=LISTAS_APOIO!$I$5),VLOOKUP(TAB_HISTORICO_MANUT[[#This Row],[SISTEMA / PERFIL]],APOIO_EXPURGO_BUILD.UP[[Perfil de perdas]:[Build Up Preventia]],2,0),VLOOKUP(TAB_HISTORICO_MANUT[[#This Row],[SISTEMA / PERFIL]],APOIO_EXPURGO_BUILD.UP[[Perfil de perdas]:[Build Up Preventia]],3,0))))) -> Man. Pneus | R8: =IF($Q8="","",(TAB_HISTORICO_MANUT[[#This Row],[Hora Final]]-TAB_HISTORICO_MANUT[[#This Row],[Hora Inicio]])*24) -> 1.4047222 | S8: =IF(TAB_HISTORICO_MANUT[[#This Row],[Tipo]]<>"Mãe","",IF(TAB_HISTORICO_MANUT[[#This Row],[AJUSTE - EXPURGO (S/N)]]<>"",TAB_HISTORICO_MANUT[[#This Row],[AJUSTE - EXPURGO (S/N)]],IF(TAB_HISTORICO_MANUT[[#This Row],[Descricao Despacho]]=LISTAS_APOIO!$I$5,"SIM",IF(ISERROR(VLOOKUP(TAB_HISTORICO_MANUT[[#This Row],[Descricao Manutencao]],EXPURGO_FILHAS[EXPURGO - FILHAS],1,0)),(_xlfn.XLOOKUP(TAB_HISTORICO_MANUT[[#This Row],[SISTEMA / PERFIL]],APOIO_EXPURGO_BUILD.UP[Perfil de perdas],APOIO_EXPURGO_BUILD.UP[Expurgo],"ADICIONAR CÓDIGO",0,1)),"SIM")))) -> NÃO | T8: =IF(AND(TAB_HISTORICO_MANUT[[#This Row],[EXPURGO Mãe]]="SIM",TAB_HISTORICO_MANUT[[#This Row],[Tipo]]="MÃE"),"EXP.MAE",IF(TAB_HISTORICO_MANUT[[#This Row],[EXPURGO Mãe]]="NÃO","NÃO EXP.MAE",T7)) -> NÃO EXP.MAE | U8: =IF(TAB_HISTORICO_MANUT[[#This Row],[CHECK. EXP. MÃE]]="EXP.MAE","NÃO",IF(TAB_HISTORICO_MANUT[[#This Row],[Tipo]]="Filha",IF(TAB_HISTORICO_MANUT[[#This Row],[AJUSTE - EXPURGO (S/N)]]="",(IF(ISERROR(VLOOKUP(TAB_HISTORICO_MANUT[[#This Row],[Descricao Manutencao]],EXPURGO_FILHAS[EXPURGO - FILHAS],1,0)),"NÃO","SIM")),TAB_HISTORICO_MANUT[[#This Row],[AJUSTE - EXPURGO (S/N)]]),"NÃO")) -> NÃO | V8: =IF(TAB_HISTORICO_MANUT[[#This Row],[EXPURGO Filhas]]="SIM",MAX(TAB_HISTORICO_MANUT[[#This Row],[Hora Final]]-TAB_HISTORICO_MANUT[[#This Row],[Hora Inicio]],0),0) -> 0 | W8: =IF(AND((TAB_HISTORICO_MANUT[[#This Row],[DURAÇÃO - PRODUTO MANUAL]]+TAB_HISTORICO_MANUT[[#This Row],[DURAÇÃO - CARTA MANUAL]])=0,OR(TAB_HISTORICO_MANUT[[#This Row],[PRODUTO]]="SIM",TAB_HISTORICO_MANUT[[#This Row],[CARTA]]="SIM")),TAB_HISTORICO_MANUT[[#This Row],[Duração Ocorrencia]],TAB_HISTORICO_MANUT[[#This Row],[DURAÇÃO - PRODUTO MANUAL]]+TAB_HISTORICO_MANUT[[#This Row],[DURAÇÃO - CARTA MANUAL]]) -> 0 | X8: =IF(AND(TAB_HISTORICO_MANUT[[#This Row],[COMPONENTE]]="SIM",TAB_HISTORICO_MANUT[[#This Row],[DURAÇÃO - COMP. MANUAL]]=""),TAB_HISTORICO_MANUT[[#This Row],[Duração Ocorrencia]],TAB_HISTORICO_MANUT[[#This Row],[DURAÇÃO - COMP. MANUAL]]) -> 0 | Y8: 46026.857 | Z8: 46026.915 | AA8: CA1014KS101 | AB8: 202600046853 | AC8: 9010 | AD8: HMC - Hora de Manutenção Corretiva | AE8: HMC - EXEC BORRACHARIA | AF8: Mãe | AG8: =IF(TAB_HISTORICO_MANUT[[#This Row],[Hora Inicio]]="","",MONTH(TAB_HISTORICO_MANUT[[#This Row],[Hora Inicio]])) -> 1 | AH8: TM_3 - BAIXA PRESSÃO DE AR PNEU TRASEIRO DIREITO EXTERNO - 202600046853 - REGULARIZAR PRESSÃO DO PNEU TDE | AI8: LOCOMOCAO | AJ8: RODA TDE | AK8: PNEU | AL8: BAIXA PRESSAO | AM8: CALIBRAR | AN8: Borracharia | AO8: Locomocao - Roda Tde | AP8: Pneu-Pressao
A9: =MONTH(TAB_HISTORICO_MANUT[[#This Row],[Hora Final]])-MONTH(TAB_HISTORICO_MANUT[[#This Row],[Hora Inicio]]) -> 0 | M9: SIM | N9: =IF(TAB_HISTORICO_MANUT[[#This Row],[AJUSTE - OCORRENCIA (0 / 1)]]<>"",TAB_HISTORICO_MANUT[[#This Row],[AJUSTE - OCORRENCIA (0 / 1)]],IF(OR(TAB_HISTORICO_MANUT[[#This Row],[Tipo]]="Filha",TAB_HISTORICO_MANUT[[#This Row],[Tipo]]=""),"",IF(AND(TAB_HISTORICO_MANUT[[#This Row],[Hora Inicio]]=Z8,TAB_HISTORICO_MANUT[[#This Row],[Equipamento]]=AA8,TAB_HISTORICO_MANUT[[#This Row],[Descricao Despacho]]=AD8),0,1))) | O9: =IF(TAB_HISTORICO_MANUT[[#This Row],[CONT. OCOR.]]="","",IF(TAB_HISTORICO_MANUT[[#This Row],[AJUSTE - SISTEMA]]<>"",TAB_HISTORICO_MANUT[[#This Row],[AJUSTE - SISTEMA]],IFERROR(VLOOKUP(TAB_HISTORICO_MANUT[[#This Row],[Sistema2]]&TAB_HISTORICO_MANUT[[#This Row],[Conjunto]],AJUSTE_PERFIL[#All],2,0),VLOOKUP(TAB_HISTORICO_MANUT[[#This Row],[Sistema2]],AJUSTE_PERFIL[],2,0)))) | P9: =IF(TAB_HISTORICO_MANUT[[#This Row],[CONT. OCOR.]]="","",IF(TAB_HISTORICO_MANUT[[#This Row],[Ajuste - Cod. Despacho]]="",TAB_HISTORICO_MANUT[[#This Row],[Descricao Despacho]],TAB_HISTORICO_MANUT[[#This Row],[Ajuste - Cod. Despacho]])) | Q9: =IF(TAB_HISTORICO_MANUT[[#This Row],[CONT. OCOR.]]="","",IF(TAB_HISTORICO_MANUT[[#This Row],[AJUSTE - BUILD UP]]<>"",TAB_HISTORICO_MANUT[[#This Row],[AJUSTE - BUILD UP]],IF(TAB_HISTORICO_MANUT[[#This Row],[Descricao Despacho]]=LISTAS_APOIO!$I$5,LISTAS_APOIO!$B$3,IF(OR(TAB_HISTORICO_MANUT[[#This Row],[Descricao Despacho]]=LISTAS_APOIO!$I$3,TAB_HISTORICO_MANUT[[#This Row],[Descricao Despacho]]=LISTAS_APOIO!$I$5),VLOOKUP(TAB_HISTORICO_MANUT[[#This Row],[SISTEMA / PERFIL]],APOIO_EXPURGO_BUILD.UP[[Perfil de perdas]:[Build Up Preventia]],2,0),VLOOKUP(TAB_HISTORICO_MANUT[[#This Row],[SISTEMA / PERFIL]],APOIO_EXPURGO_BUILD.UP[[Perfil de perdas]:[Build Up Preventia]],3,0))))) | R9: =IF($Q9="","",(TAB_HISTORICO_MANUT[[#This Row],[Hora Final]]-TAB_HISTORICO_MANUT[[#This Row],[Hora Inicio]])*24) | S9: =IF(TAB_HISTORICO_MANUT[[#This Row],[Tipo]]<>"Mãe","",IF(TAB_HISTORICO_MANUT[[#This Row],[AJUSTE - EXPURGO (S/N)]]<>"",TAB_HISTORICO_MANUT[[#This Row],[AJUSTE - EXPURGO (S/N)]],IF(TAB_HISTORICO_MANUT[[#This Row],[Descricao Despacho]]=LISTAS_APOIO!$I$5,"SIM",IF(ISERROR(VLOOKUP(TAB_HISTORICO_MANUT[[#This Row],[Descricao Manutencao]],EXPURGO_FILHAS[EXPURGO - FILHAS],1,0)),(_xlfn.XLOOKUP(TAB_HISTORICO_MANUT[[#This Row],[SISTEMA / PERFIL]],APOIO_EXPURGO_BUILD.UP[Perfil de perdas],APOIO_EXPURGO_BUILD.UP[Expurgo],"ADICIONAR CÓDIGO",0,1)),"SIM")))) | T9: =IF(AND(TAB_HISTORICO_MANUT[[#This Row],[EXPURGO Mãe]]="SIM",TAB_HISTORICO_MANUT[[#This Row],[Tipo]]="MÃE"),"EXP.MAE",IF(TAB_HISTORICO_MANUT[[#This Row],[EXPURGO Mãe]]="NÃO","NÃO EXP.MAE",T8)) -> NÃO EXP.MAE | U9: =IF(TAB_HISTORICO_MANUT[[#This Row],[CHECK. EXP. MÃE]]="EXP.MAE","NÃO",IF(TAB_HISTORICO_MANUT[[#This Row],[Tipo]]="Filha",IF(TAB_HISTORICO_MANUT[[#This Row],[AJUSTE - EXPURGO (S/N)]]="",(IF(ISERROR(VLOOKUP(TAB_HISTORICO_MANUT[[#This Row],[Descricao Manutencao]],EXPURGO_FILHAS[EXPURGO - FILHAS],1,0)),"NÃO","SIM")),TAB_HISTORICO_MANUT[[#This Row],[AJUSTE - EXPURGO (S/N)]]),"NÃO")) -> SIM | V9: =IF(TAB_HISTORICO_MANUT[[#This Row],[EXPURGO Filhas]]="SIM",MAX(TAB_HISTORICO_MANUT[[#This Row],[Hora Final]]-TAB_HISTORICO_MANUT[[#This Row],[Hora Inicio]],0),0) -> 0.046999664 | W9: =IF(AND((TAB_HISTORICO_MANUT[[#This Row],[DURAÇÃO - PRODUTO MANUAL]]+TAB_HISTORICO_MANUT[[#This Row],[DURAÇÃO - CARTA MANUAL]])=0,OR(TAB_HISTORICO_MANUT[[#This Row],[PRODUTO]]="SIM",TAB_HISTORICO_MANUT[[#This Row],[CARTA]]="SIM")),TAB_HISTORICO_MANUT[[#This Row],[Duração Ocorrencia]],TAB_HISTORICO_MANUT[[#This Row],[DURAÇÃO - PRODUTO MANUAL]]+TAB_HISTORICO_MANUT[[#This Row],[DURAÇÃO - CARTA MANUAL]]) -> 0 | X9: =IF(AND(TAB_HISTORICO_MANUT[[#This Row],[COMPONENTE]]="SIM",TAB_HISTORICO_MANUT[[#This Row],[DURAÇÃO - COMP. MANUAL]]=""),TAB_HISTORICO_MANUT[[#This Row],[Duração Ocorrencia]],TAB_HISTORICO_MANUT[[#This Row],[DURAÇÃO - COMP. MANUAL]]) -> 0 | Y9: 46026.868 | Z9: 46026.915 | AA9: CA1014KS101 | AB9: 202600046853 | AC9: 9010 | AD9: HMC - Hora de Manutenção Corretiva | AE9: HMC - EXEC BORRACHARIA | AF9: Filha | AG9: =IF(TAB_HISTORICO_MANUT[[#This Row],[Hora Inicio]]="","",MONTH(TAB_HISTORICO_MANUT[[#This Row],[Hora Inicio]])) -> 1 | AH9: TM_3 - BAIXA PRESSÃO DE AR PNEU TRASEIRO DIREITO EXTERNO - 202600046853 - REGULARIZAR PRESSÃO DO PNEU TDE | AI9: LOCOMOCAO | AJ9: RODA TDE | AK9: PNEU | AL9: BAIXA PRESSAO | AM9: CALIBRAR | AN9: Borracharia | AO9: Locomocao - Roda Tde | AP9: Pneu-Pressao
A10: =MONTH(TAB_HISTORICO_MANUT[[#This Row],[Hora Final]])-MONTH(TAB_HISTORICO_MANUT[[#This Row],[Hora Inicio]]) -> 0 | N10: =IF(TAB_HISTORICO_MANUT[[#This Row],[AJUSTE - OCORRENCIA (0 / 1)]]<>"",TAB_HISTORICO_MANUT[[#This Row],[AJUSTE - OCORRENCIA (0 / 1)]],IF(OR(TAB_HISTORICO_MANUT[[#This Row],[Tipo]]="Filha",TAB_HISTORICO_MANUT[[#This Row],[Tipo]]=""),"",IF(AND(TAB_HISTORICO_MANUT[[#This Row],[Hora Inicio]]=Z9,TAB_HISTORICO_MANUT[[#This Row],[Equipamento]]=AA9,TAB_HISTORICO_MANUT[[#This Row],[Descricao Despacho]]=AD9),0,1))) -> 1 | O10: =IF(TAB_HISTORICO_MANUT[[#This Row],[CONT. OCOR.]]="","",IF(TAB_HISTORICO_MANUT[[#This Row],[AJUSTE - SISTEMA]]<>"",TAB_HISTORICO_MANUT[[#This Row],[AJUSTE - SISTEMA]],IFERROR(VLOOKUP(TAB_HISTORICO_MANUT[[#This Row],[Sistema2]]&TAB_HISTORICO_MANUT[[#This Row],[Conjunto]],AJUSTE_PERFIL[#All],2,0),VLOOKUP(TAB_HISTORICO_MANUT[[#This Row],[Sistema2]],AJUSTE_PERFIL[],2,0)))) -> SISTEMA DE FREIO | P10: =IF(TAB_HISTORICO_MANUT[[#This Row],[CONT. OCOR.]]="","",IF(TAB_HISTORICO_MANUT[[#This Row],[Ajuste - Cod. Despacho]]="",TAB_HISTORICO_MANUT[[#This Row],[Descricao Despacho]],TAB_HISTORICO_MANUT[[#This Row],[Ajuste - Cod. Despacho]])) -> HMC - Hora de Manutenção Corretiva | Q10: =IF(TAB_HISTORICO_MANUT[[#This Row],[CONT. OCOR.]]="","",IF(TAB_HISTORICO_MANUT[[#This Row],[AJUSTE - BUILD UP]]<>"",TAB_HISTORICO_MANUT[[#This Row],[AJUSTE - BUILD UP]],IF(TAB_HISTORICO_MANUT[[#This Row],[Descricao Despacho]]=LISTAS_APOIO!$I$5,LISTAS_APOIO!$B$3,IF(OR(TAB_HISTORICO_MANUT[[#This Row],[Descricao Despacho]]=LISTAS_APOIO!$I$3,TAB_HISTORICO_MANUT[[#This Row],[Descricao Despacho]]=LISTAS_APOIO!$I$5),VLOOKUP(TAB_HISTORICO_MANUT[[#This Row],[SISTEMA / PERFIL]],APOIO_EXPURGO_BUILD.UP[[Perfil de perdas]:[Build Up Preventia]],2,0),VLOOKUP(TAB_HISTORICO_MANUT[[#This Row],[SISTEMA / PERFIL]],APOIO_EXPURGO_BUILD.UP[[Perfil de perdas]:[Build Up Preventia]],3,0))))) -> Corretivas | R10: =IF($Q10="","",(TAB_HISTORICO_MANUT[[#This Row],[Hora Final]]-TAB_HISTORICO_MANUT[[#This Row],[Hora Inicio]])*24) -> 6.1544444 | S10: =IF(TAB_HISTORICO_MANUT[[#This Row],[Tipo]]<>"Mãe","",IF(TAB_HISTORICO_MANUT[[#This Row],[AJUSTE - EXPURGO (S/N)]]<>"",TAB_HISTORICO_MANUT[[#This Row],[AJUSTE - EXPURGO (S/N)]],IF(TAB_HISTORICO_MANUT[[#This Row],[Descricao Despacho]]=LISTAS_APOIO!$I$5,"SIM",IF(ISERROR(VLOOKUP(TAB_HISTORICO_MANUT[[#This Row],[Descricao Manutencao]],EXPURGO_FILHAS[EXPURGO - FILHAS],1,0)),(_xlfn.XLOOKUP(TAB_HISTORICO_MANUT[[#This Row],[SISTEMA / PERFIL]],APOIO_EXPURGO_BUILD.UP[Perfil de perdas],APOIO_EXPURGO_BUILD.UP[Expurgo],"ADICIONAR CÓDIGO",0,1)),"SIM")))) -> NÃO | T10: =IF(AND(TAB_HISTORICO_MANUT[[#This Row],[EXPURGO Mãe]]="SIM",TAB_HISTORICO_MANUT[[#This Row],[Tipo]]="MÃE"),"EXP.MAE",IF(TAB_HISTORICO_MANUT[[#This Row],[EXPURGO Mãe]]="NÃO","NÃO EXP.MAE",T9)) -> NÃO EXP.MAE | U10: =IF(TAB_HISTORICO_MANUT[[#This Row],[CHECK. EXP. MÃE]]="EXP.MAE","NÃO",IF(TAB_HISTORICO_MANUT[[#This Row],[Tipo]]="Filha",IF(TAB_HISTORICO_MANUT[[#This Row],[AJUSTE - EXPURGO (S/N)]]="",(IF(ISERROR(VLOOKUP(TAB_HISTORICO_MANUT[[#This Row],[Descricao Manutencao]],EXPURGO_FILHAS[EXPURGO - FILHAS],1,0)),"NÃO","SIM")),TAB_HISTORICO_MANUT[[#This Row],[AJUSTE - EXPURGO (S/N)]]),"NÃO")) -> NÃO | V10: =IF(TAB_HISTORICO_MANUT[[#This Row],[EXPURGO Filhas]]="SIM",MAX(TAB_HISTORICO_MANUT[[#This Row],[Hora Final]]-TAB_HISTORICO_MANUT[[#This Row],[Hora Inicio]],0),0) -> 0 | W10: =IF(AND((TAB_HISTORICO_MANUT[[#This Row],[DURAÇÃO - PRODUTO MANUAL]]+TAB_HISTORICO_MANUT[[#This Row],[DURAÇÃO - CARTA MANUAL]])=0,OR(TAB_HISTORICO_MANUT[[#This Row],[PRODUTO]]="SIM",TAB_HISTORICO_MANUT[[#This Row],[CARTA]]="SIM")),TAB_HISTORICO_MANUT[[#This Row],[Duração Ocorrencia]],TAB_HISTORICO_MANUT[[#This Row],[DURAÇÃO - PRODUTO MANUAL]]+TAB_HISTORICO_MANUT[[#This Row],[DURAÇÃO - CARTA MANUAL]]) -> 0 | X10: =IF(AND(TAB_HISTORICO_MANUT[[#This Row],[COMPONENTE]]="SIM",TAB_HISTORICO_MANUT[[#This Row],[DURAÇÃO - COMP. MANUAL]]=""),TAB_HISTORICO_MANUT[[#This Row],[Duração Ocorrencia]],TAB_HISTORICO_MANUT[[#This Row],[DURAÇÃO - COMP. MANUAL]]) -> 0 | Y10: 46027.343 | Z10: 46027.6 | AA10: CA1014KS101 | AB10: 202600057063 | AC10: 9000 | AD10: HMC - Hora de Manutenção Corretiva | AE10: HMC - EXEC MANUT | AF10: Mãe | AG10: =IF(TAB_HISTORICO_MANUT[[#This Row],[Hora Inicio]]="","",MONTH(TAB_HISTORICO_MANUT[[#This Row],[Hora Inicio]])) -> 1 | AH10: 202600057063 VAZAMENTO DE DISEL - SUBS MANGUERIA DO OLEO | AI10: FRENAGEM | AJ10: FREIO | AK10: MANG. FILTRO | AL10: VAZAMENTO | AM10: SUBSTITUIR | AN10: Mecânica | AO10: Motor diesel | AP10: Filtro de Combustivel
A11: =MONTH(TAB_HISTORICO_MANUT[[#This Row],[Hora Final]])-MONTH(TAB_HISTORICO_MANUT[[#This Row],[Hora Inicio]]) -> 0 | N11: =IF(TAB_HISTORICO_MANUT[[#This Row],[AJUSTE - OCORRENCIA (0 / 1)]]<>"",TAB_HISTORICO_MANUT[[#This Row],[AJUSTE - OCORRENCIA (0 / 1)]],IF(OR(TAB_HISTORICO_MANUT[[#This Row],[Tipo]]="Filha",TAB_HISTORICO_MANUT[[#This Row],[Tipo]]=""),"",IF(AND(TAB_HISTORICO_MANUT[[#This Row],[Hora Inicio]]=Z10,TAB_HISTORICO_MANUT[[#This Row],[Equipamento]]=AA10,TAB_HISTORICO_MANUT[[#This Row],[Descricao Despacho]]=AD10),0,1))) -> 1 | O11: =IF(TAB_HISTORICO_MANUT[[#This Row],[CONT. OCOR.]]="","",IF(TAB_HISTORICO_MANUT[[#This Row],[AJUSTE - SISTEMA]]<>"",TAB_HISTORICO_MANUT[[#This Row],[AJUSTE - SISTEMA]],IFERROR(VLOOKUP(TAB_HISTORICO_MANUT[[#This Row],[Sistema2]]&TAB_HISTORICO_MANUT[[#This Row],[Conjunto]],AJUSTE_PERFIL[#All],2,0),VLOOKUP(TAB_HISTORICO_MANUT[[#This Row],[Sistema2]],AJUSTE_PERFIL[],2,0)))) -> AR CONDICIONADO | P11: =IF(TAB_HISTORICO_MANUT[[#This Row],[CONT. OCOR.]]="","",IF(TAB_HISTORICO_MANUT[[#This Row],[Ajuste - Cod. Despacho]]="",TAB_HISTORICO_MANUT[[#This Row],[Descricao Despacho]],TAB_HISTORICO_MANUT[[#This Row],[Ajuste - Cod. Despacho]])) -> HMC - Hora de Manutenção Corretiva | Q11: =IF(TAB_HISTORICO_MANUT[[#This Row],[CONT. OCOR.]]="","",IF(TAB_HISTORICO_MANUT[[#This Row],[AJUSTE - BUILD UP]]<>"",TAB_HISTORICO_MANUT[[#This Row],[AJUSTE - BUILD UP]],IF(TAB_HISTORICO_MANUT[[#This Row],[Descricao Despacho]]=LISTAS_APOIO!$I$5,LISTAS_APOIO!$B$3,IF(OR(TAB_HISTORICO_MANUT[[#This Row],[Descricao Despacho]]=LISTAS_APOIO!$I$3,TAB_HISTORICO_MANUT[[#This Row],[Descricao Despacho]]=LISTAS_APOIO!$I$5),VLOOKUP(TAB_HISTORICO_MANUT[[#This Row],[SISTEMA / PERFIL]],APOIO_EXPURGO_BUILD.UP[[Perfil de perdas]:[Build Up Preventia]],2,0),VLOOKUP(TAB_HISTORICO_MANUT[[#This Row],[SISTEMA / PERFIL]],APOIO_EXPURGO_BUILD.UP[[Perfil de perdas]:[Build Up Preventia]],3,0))))) -> Corretivas | R11: =IF($Q11="","",(TAB_HISTORICO_MANUT[[#This Row],[Hora Final]]-TAB_HISTORICO_MANUT[[#This Row],[Hora Inicio]])*24) -> 9.1775 | S11: =IF(TAB_HISTORICO_MANUT[[#This Row],[Tipo]]<>"Mãe","",IF(TAB_HISTORICO_MANUT[[#This Row],[AJUSTE - EXPURGO (S/N)]]<>"",TAB_HISTORICO_MANUT[[#This Row],[AJUSTE - EXPURGO (S/N)]],IF(TAB_HISTORICO_MANUT[[#This Row],[Descricao Despacho]]=LISTAS_APOIO!$I$5,"SIM",IF(ISERROR(VLOOKUP(TAB_HISTORICO_MANUT[[#This Row],[Descricao Manutencao]],EXPURGO_FILHAS[EXPURGO - FILHAS],1,0)),(_xlfn.XLOOKUP(TAB_HISTORICO_MANUT[[#This Row],[SISTEMA / PERFIL]],APOIO_EXPURGO_BUILD.UP[Perfil de perdas],APOIO_EXPURGO_BUILD.UP[Expurgo],"ADICIONAR CÓDIGO",0,1)),"SIM")))) -> NÃO | T11: =IF(AND(TAB_HISTORICO_MANUT[[#This Row],[EXPURGO Mãe]]="SIM",TAB_HISTORICO_MANUT[[#This Row],[Tipo]]="MÃE"),"EXP.MAE",IF(TAB_HISTORICO_MANUT[[#This Row],[EXPURGO Mãe]]="NÃO","NÃO EXP.MAE",T10)) -> NÃO EXP.MAE | U11: =IF(TAB_HISTORICO_MANUT[[#This Row],[CHECK. EXP. MÃE]]="EXP.MAE","NÃO",IF(TAB_HISTORICO_MANUT[[#This Row],[Tipo]]="Filha",IF(TAB_HISTORICO_MANUT[[#This Row],[AJUSTE - EXPURGO (S/N)]]="",(IF(ISERROR(VLOOKUP(TAB_HISTORICO_MANUT[[#This Row],[Descricao Manutencao]],EXPURGO_FILHAS[EXPURGO - FILHAS],1,0)),"NÃO","SIM")),TAB_HISTORICO_MANUT[[#This Row],[AJUSTE - EXPURGO (S/N)]]),"NÃO")) -> NÃO | V11: =IF(TAB_HISTORICO_MANUT[[#This Row],[EXPURGO Filhas]]="SIM",MAX(TAB_HISTORICO_MANUT[[#This Row],[Hora Final]]-TAB_HISTORICO_MANUT[[#This Row],[Hora Inicio]],0),0) -> 0 | W11: =IF(AND((TAB_HISTORICO_MANUT[[#This Row],[DURAÇÃO - PRODUTO MANUAL]]+TAB_HISTORICO_MANUT[[#This Row],[DURAÇÃO - CARTA MANUAL]])=0,OR(TAB_HISTORICO_MANUT[[#This Row],[PRODUTO]]="SIM",TAB_HISTORICO_MANUT[[#This Row],[CARTA]]="SIM")),TAB_HISTORICO_MANUT[[#This Row],[Duração Ocorrencia]],TAB_HISTORICO_MANUT[[#This Row],[DURAÇÃO - PRODUTO MANUAL]]+TAB_HISTORICO_MANUT[[#This Row],[DURAÇÃO - CARTA MANUAL]]) -> 0 | X11: =IF(AND(TAB_HISTORICO_MANUT[[#This Row],[COMPONENTE]]="SIM",TAB_HISTORICO_MANUT[[#This Row],[DURAÇÃO - COMP. MANUAL]]=""),TAB_HISTORICO_MANUT[[#This Row],[Duração Ocorrencia]],TAB_HISTORICO_MANUT[[#This Row],[DURAÇÃO - COMP. MANUAL]]) -> 0 | Y11: 46027.776 | Z11: 46028.158 | AA11: CA1014KS101 | AB11: 202600065845 | AC11: 9000 | AD11: HMC - Hora de Manutenção Corretiva | AE11: HMC - EXEC MANUT | AF11: Mãe | AG11: =IF(TAB_HISTORICO_MANUT[[#This Row],[Hora Inicio]]="","",MONTH(TAB_HISTORICO_MANUT[[#This Row],[Hora Inicio]])) -> 1 | AH11: FALHA NO AR CONDICIONADO - 202600065845 - SUBSTITUIDO COMPRESSOR DO A/C MT: 1150588 | AI11: AR CONDICIONADO | AJ11: COMPRESSOR | AK11: COMPRESSOR | AL11: AVARIA | AM11: SUBSTITUIR | AN11: Mecânica | AO11: Ar Condicionado - Compressor | AP11: Compressor-Avaria
A12: =MONTH(TAB_HISTORICO_MANUT[[#This Row],[Hora Final]])-MONTH(TAB_HISTORICO_MANUT[[#This Row],[Hora Inicio]]) -> 0 | N12: =IF(TAB_HISTORICO_MANUT[[#This Row],[AJUSTE - OCORRENCIA (0 / 1)]]<>"",TAB_HISTORICO_MANUT[[#This Row],[AJUSTE - OCORRENCIA (0 / 1)]],IF(OR(TAB_HISTORICO_MANUT[[#This Row],[Tipo]]="Filha",TAB_HISTORICO_MANUT[[#This Row],[Tipo]]=""),"",IF(AND(TAB_HISTORICO_MANUT[[#This Row],[Hora Inicio]]=Z11,TAB_HISTORICO_MANUT[[#This Row],[Equipamento]]=AA11,TAB_HISTORICO_MANUT[[#This Row],[Descricao Despacho]]=AD11),0,1))) -> 1 | O12: =IF(TAB_HISTORICO_MANUT[[#This Row],[CONT. OCOR.]]="","",IF(TAB_HISTORICO_MANUT[[#This Row],[AJUSTE - SISTEMA]]<>"",TAB_HISTORICO_MANUT[[#This Row],[AJUSTE - SISTEMA]],IFERROR(VLOOKUP(TAB_HISTORICO_MANUT[[#This Row],[Sistema2]]&TAB_HISTORICO_MANUT[[#This Row],[Conjunto]],AJUSTE_PERFIL[#All],2,0),VLOOKUP(TAB_HISTORICO_MANUT[[#This Row],[Sistema2]],AJUSTE_PERFIL[],2,0)))) -> AR CONDICIONADO | P12: =IF(TAB_HISTORICO_MANUT[[#This Row],[CONT. OCOR.]]="","",IF(TAB_HISTORICO_MANUT[[#This Row],[Ajuste - Cod. Despacho]]="",TAB_HISTORICO_MANUT[[#This Row],[Descricao Despacho]],TAB_HISTORICO_MANUT[[#This Row],[Ajuste - Cod. Despacho]])) -> HMC - Hora de Manutenção Corretiva | Q12: =IF(TAB_HISTORICO_MANUT[[#This Row],[CONT. OCOR.]]="","",IF(TAB_HISTORICO_MANUT[[#This Row],[AJUSTE - BUILD UP]]<>"",TAB_HISTORICO_MANUT[[#This Row],[AJUSTE - BUILD UP]],IF(TAB_HISTORICO_MANUT[[#This Row],[Descricao Despacho]]=LISTAS_APOIO!$I$5,LISTAS_APOIO!$B$3,IF(OR(TAB_HISTORICO_MANUT[[#This Row],[Descricao Despacho]]=LISTAS_APOIO!$I$3,TAB_HISTORICO_MANUT[[#This Row],[Descricao Despacho]]=LISTAS_APOIO!$I$5),VLOOKUP(TAB_HISTORICO_MANUT[[#This Row],[SISTEMA / PERFIL]],APOIO_EXPURGO_BUILD.UP[[Perfil de perdas]:[Build Up Preventia]],2,0),VLOOKUP(TAB_HISTORICO_MANUT[[#This Row],[SISTEMA / PERFIL]],APOIO_EXPURGO_BUILD.UP[[Perfil de perdas]:[Build Up Preventia]],3,0))))) -> Corretivas | R12: =IF($Q12="","",(TAB_HISTORICO_MANUT[[#This Row],[Hora Final]]-TAB_HISTORICO_MANUT[[#This Row],[Hora Inicio]])*24) -> 3.3641667 | S12: =IF(TAB_HISTORICO_MANUT[[#This Row],[Tipo]]<>"Mãe","",IF(TAB_HISTORICO_MANUT[[#This Row],[AJUSTE - EXPURGO (S/N)]]<>"",TAB_HISTORICO_MANUT[[#This Row],[AJUSTE - EXPURGO (S/N)]],IF(TAB_HISTORICO_MANUT[[#This Row],[Descricao Despacho]]=LISTAS_APOIO!$I$5,"SIM",IF(ISERROR(VLOOKUP(TAB_HISTORICO_MANUT[[#This Row],[Descricao Manutencao]],EXPURGO_FILHAS[EXPURGO - FILHAS],1,0)),(_xlfn.XLOOKUP(TAB_HISTORICO_MANUT[[#This Row],[SISTEMA / PERFIL]],APOIO_EXPURGO_BUILD.UP[Perfil de perdas],APOIO_EXPURGO_BUILD.UP[Expurgo],"ADICIONAR CÓDIGO",0,1)),"SIM")))) -> NÃO | T12: =IF(AND(TAB_HISTORICO_MANUT[[#This Row],[EXPURGO Mãe]]="SIM",TAB_HISTORICO_MANUT[[#This Row],[Tipo]]="MÃE"),"EXP.MAE",IF(TAB_HISTORICO_MANUT[[#This Row],[EXPURGO Mãe]]="NÃO","NÃO EXP.MAE",T11)) -> NÃO EXP.MAE | U12: =IF(TAB_HISTORICO_MANUT[[#This Row],[CHECK. EXP. MÃE]]="EXP.MAE","NÃO",IF(TAB_HISTORICO_MANUT[[#This Row],[Tipo]]="Filha",IF(TAB_HISTORICO_MANUT[[#This Row],[AJUSTE - EXPURGO (S/N)]]="",(IF(ISERROR(VLOOKUP(TAB_HISTORICO_MANUT[[#This Row],[Descricao Manutencao]],EXPURGO_FILHAS[EXPURGO - FILHAS],1,0)),"NÃO","SIM")),TAB_HISTORICO_MANUT[[#This Row],[AJUSTE - EXPURGO (S/N)]]),"NÃO")) -> NÃO | V12: =IF(TAB_HISTORICO_MANUT[[#This Row],[EXPURGO Filhas]]="SIM",MAX(TAB_HISTORICO_MANUT[[#This Row],[Hora Final]]-TAB_HISTORICO_MANUT[[#This Row],[Hora Inicio]],0),0) -> 0 | W12: =IF(AND((TAB_HISTORICO_MANUT[[#This Row],[DURAÇÃO - PRODUTO MANUAL]]+TAB_HISTORICO_MANUT[[#This Row],[DURAÇÃO - CARTA MANUAL]])=0,OR(TAB_HISTORICO_MANUT[[#This Row],[PRODUTO]]="SIM",TAB_HISTORICO_MANUT[[#This Row],[CARTA]]="SIM")),TAB_HISTORICO_MANUT[[#This Row],[Duração Ocorrencia]],TAB_HISTORICO_MANUT[[#This Row],[DURAÇÃO - PRODUTO MANUAL]]+TAB_HISTORICO_MANUT[[#This Row],[DURAÇÃO - CARTA MANUAL]]) -> 0 | X12: =IF(AND(TAB_HISTORICO_MANUT[[#This Row],[COMPONENTE]]="SIM",TAB_HISTORICO_MANUT[[#This Row],[DURAÇÃO - COMP. MANUAL]]=""),TAB_HISTORICO_MANUT[[#This Row],[Duração Ocorrencia]],TAB_HISTORICO_MANUT[[#This Row],[DURAÇÃO - COMP. MANUAL]]) -> 0 | Y12: 46028.559 | Z12: 46028.699 | AA12: CA1014KS101 | AB12: 202600082410 | AC12: 9000 | AD12: HMC - Hora de Manutenção Corretiva | AE12: HMC - EXEC MANUT | AF12: Mãe | AG12: =IF(TAB_HISTORICO_MANUT[[#This Row],[Hora Inicio]]="","",MONTH(TAB_HISTORICO_MANUT[[#This Row],[Hora Inicio]])) -> 1 | AH12: 202600082410 AR CONDICIONADO - REALIZADO LIMPEZA NO AR CONDICONADO , SUBSTITUIDO FILTRO DESSECANTE E COMPLETADO CARGA DE GÁS | AI12: AR CONDICIONADO | AJ12: LINHA DE GAS | AK12: FILTRO | AL12: OBSTRUIDO | AM12: SUBSTITUIR | AN12: Mecânica | AO12: Ar Condicionado - Linha Gas | AP12: Mangueira/Fixação
A13: =MONTH(TAB_HISTORICO_MANUT[[#This Row],[Hora Final]])-MONTH(TAB_HISTORICO_MANUT[[#This Row],[Hora Inicio]]) -> 0 | N13: =IF(TAB_HISTORICO_MANUT[[#This Row],[AJUSTE - OCORRENCIA (0 / 1)]]<>"",TAB_HISTORICO_MANUT[[#This Row],[AJUSTE - OCORRENCIA (0 / 1)]],IF(OR(TAB_HISTORICO_MANUT[[#This Row],[Tipo]]="Filha",TAB_HISTORICO_MANUT[[#This Row],[Tipo]]=""),"",IF(AND(TAB_HISTORICO_MANUT[[#This Row],[Hora Inicio]]=Z12,TAB_HISTORICO_MANUT[[#This Row],[Equipamento]]=AA12,TAB_HISTORICO_MANUT[[#This Row],[Descricao Despacho]]=AD12),0,1))) -> 1 | O13: =IF(TAB_HISTORICO_MANUT[[#This Row],[CONT. OCOR.]]="","",IF(TAB_HISTORICO_MANUT[[#This Row],[AJUSTE - SISTEMA]]<>"",TAB_HISTORICO_MANUT[[#This Row],[AJUSTE - SISTEMA]],IFERROR(VLOOKUP(TAB_HISTORICO_MANUT[[#This Row],[Sistema2]]&TAB_HISTORICO_MANUT[[#This Row],[Conjunto]],AJUSTE_PERFIL[#All],2,0),VLOOKUP(TAB_HISTORICO_MANUT[[#This Row],[Sistema2]],AJUSTE_PERFIL[],2,0)))) -> LOCOMOÇÃO | P13: =IF(TAB_HISTORICO_MANUT[[#This Row],[CONT. OCOR.]]="","",IF(TAB_HISTORICO_MANUT[[#This Row],[Ajuste - Cod. Despacho]]="",TAB_HISTORICO_MANUT[[#This Row],[Descricao Despacho]],TAB_HISTORICO_MANUT[[#This Row],[Ajuste - Cod. Despacho]])) -> HMC - Hora de Manutenção Corretiva | Q13: =IF(TAB_HISTORICO_MANUT[[#This Row],[CONT. OCOR.]]="","",IF(TAB_HISTORICO_MANUT[[#This Row],[AJUSTE - BUILD UP]]<>"",TAB_HISTORICO_MANUT[[#This Row],[AJUSTE - BUILD UP]],IF(TAB_HISTORICO_MANUT[[#This Row],[Descricao Despacho]]=LISTAS_APOIO!$I$5,LISTAS_APOIO!$B$3,IF(OR(TAB_HISTORICO_MANUT[[#This Row],[Descricao Despacho]]=LISTAS_APOIO!$I$3,TAB_HISTORICO_MANUT[[#This Row],[Descricao Despacho]]=LISTAS_APOIO!$I$5),VLOOKUP(TAB_HISTORICO_MANUT[[#This Row],[SISTEMA / PERFIL]],APOIO_EXPURGO_BUILD.UP[[Perfil de perdas]:[Build Up Preventia]],2,0),VLOOKUP(TAB_HISTORICO_MANUT[[#This Row],[SISTEMA / PERFIL]],APOIO_EXPURGO_BUILD.UP[[Perfil de perdas]:[Build Up Preventia]],3,0))))) -> Man. Pneus | R13: =IF($Q13="","",(TAB_HISTORICO_MANUT[[#This Row],[Hora Final]]-TAB_HISTORICO_MANUT[[#This Row],[Hora Inicio]])*24) -> 1.6947222 | S13: =IF(TAB_HISTORICO_MANUT[[#This Row],[Tipo]]<>"Mãe","",IF(TAB_HISTORICO_MANUT[[#This Row],[AJUSTE - EXPURGO (S/N)]]<>"",TAB_HISTORICO_MANUT[[#This Row],[AJUSTE - EXPURGO (S/N)]],IF(TAB_HISTORICO_MANUT[[#This Row],[Descricao Despacho]]=LISTAS_APOIO!$I$5,"SIM",IF(ISERROR(VLOOKUP(TAB_HISTORICO_MANUT[[#This Row],[Descricao Manutencao]],EXPURGO_FILHAS[EXPURGO - FILHAS],1,0)),(_xlfn.XLOOKUP(TAB_HISTORICO_MANUT[[#This Row],[SISTEMA / PERFIL]],APOIO_EXPURGO_BUILD.UP[Perfil de perdas],APOIO_EXPURGO_BUILD.UP[Expurgo],"ADICIONAR CÓDIGO",0,1)),"SIM")))) -> NÃO | T13: =IF(AND(TAB_HISTORICO_MANUT[[#This Row],[EXPURGO Mãe]]="SIM",TAB_HISTORICO_MANUT[[#This Row],[Tipo]]="MÃE"),"EXP.MAE",IF(TAB_HISTORICO_MANUT[[#This Row],[EXPURGO Mãe]]="NÃO","NÃO EXP.MAE",T12)) -> NÃO EXP.MAE | U13: =IF(TAB_HISTORICO_MANUT[[#This Row],[CHECK. EXP. MÃE]]="EXP.MAE","NÃO",IF(TAB_HISTORICO_MANUT[[#This Row],[Tipo]]="Filha",IF(TAB_HISTORICO_MANUT[[#This Row],[AJUSTE - EXPURGO (S/N)]]="",(IF(ISERROR(VLOOKUP(TAB_HISTORICO_MANUT[[#This Row],[Descricao Manutencao]],EXPURGO_FILHAS[EXPURGO - FILHAS],1,0)),"NÃO","SIM")),TAB_HISTORICO_MANUT[[#This Row],[AJUSTE - EXPURGO (S/N)]]),"NÃO")) -> NÃO | V13: =IF(TAB_HISTORICO_MANUT[[#This Row],[EXPURGO Filhas]]="SIM",MAX(TAB_HISTORICO_MANUT[[#This Row],[Hora Final]]-TAB_HISTORICO_MANUT[[#This Row],[Hora Inicio]],0),0) -> 0 | W13: =IF(AND((TAB_HISTORICO_MANUT[[#This Row],[DURAÇÃO - PRODUTO MANUAL]]+TAB_HISTORICO_MANUT[[#This Row],[DURAÇÃO - CARTA MANUAL]])=0,OR(TAB_HISTORICO_MANUT[[#This Row],[PRODUTO]]="SIM",TAB_HISTORICO_MANUT[[#This Row],[CARTA]]="SIM")),TAB_HISTORICO_MANUT[[#This Row],[Duração Ocorrencia]],TAB_HISTORICO_MANUT[[#This Row],[DURAÇÃO - PRODUTO MANUAL]]+TAB_HISTORICO_MANUT[[#This Row],[DURAÇÃO - CARTA MANUAL]]) -> 0 | X13: =IF(AND(TAB_HISTORICO_MANUT[[#This Row],[COMPONENTE]]="SIM",TAB_HISTORICO_MANUT[[#This Row],[DURAÇÃO - COMP. MANUAL]]=""),TAB_HISTORICO_MANUT[[#This Row],[Duração Ocorrencia]],TAB_HISTORICO_MANUT[[#This Row],[DURAÇÃO - COMP. MANUAL]]) -> 0 | Y13: 46028.769 | Z13: 46028.839 | AA13: CA1014KS101 | AB13: 202600085645 | AC13: 9010 | AD13: HMC - Hora de Manutenção Corretiva | AE13: HMC - EXEC BORRACHARIA | AF13: Mãe | AG13: =IF(TAB_HISTORICO_MANUT[[#This Row],[Hora Inicio]]="","",MONTH(TAB_HISTORICO_MANUT[[#This Row],[Hora Inicio]])) -> 1 | AH13: BAIXA PRESSÃO DE AR DO PNEU - 202600085645 - REALIZADO CALIBRAGEM DO PNEU TRASEIRO DIREITO EXTERNO MT: 81036838 | AI13: LOCOMOCAO | AJ13: RODA TDE | AK13: PNEU | AL13: BAIXA PRESSAO | AM13: CALIBRAR | AN13: Borracharia | AO13: Locomocao - Roda Tde | AP13: Pneu-Pressao
A14: =MONTH(TAB_HISTORICO_MANUT[[#This Row],[Hora Final]])-MONTH(TAB_HISTORICO_MANUT[[#This Row],[Hora Inicio]]) -> 0 | M14: SIM | N14: =IF(TAB_HISTORICO_MANUT[[#This Row],[AJUSTE - OCORRENCIA (0 / 1)]]<>"",TAB_HISTORICO_MANUT[[#This Row],[AJUSTE - OCORRENCIA (0 / 1)]],IF(OR(TAB_HISTORICO_MANUT[[#This Row],[Tipo]]="Filha",TAB_HISTORICO_MANUT[[#This Row],[Tipo]]=""),"",IF(AND(TAB_HISTORICO_MANUT[[#This Row],[Hora Inicio]]=Z13,TAB_HISTORICO_MANUT[[#This Row],[Equipamento]]=AA13,TAB_HISTORICO_MANUT[[#This Row],[Descricao Despacho]]=AD13),0,1))) | O14: =IF(TAB_HISTORICO_MANUT[[#This Row],[CONT. OCOR.]]="","",IF(TAB_HISTORICO_MANUT[[#This Row],[AJUSTE - SISTEMA]]<>"",TAB_HISTORICO_MANUT[[#This Row],[AJUSTE - SISTEMA]],IFERROR(VLOOKUP(TAB_HISTORICO_MANUT[[#This Row],[Sistema2]]&TAB_HISTORICO_MANUT[[#This Row],[Conjunto]],AJUSTE_PERFIL[#All],2,0),VLOOKUP(TAB_HISTORICO_MANUT[[#This Row],[Sistema2]],AJUSTE_PERFIL[],2,0)))) | P14: =IF(TAB_HISTORICO_MANUT[[#This Row],[CONT. OCOR.]]="","",IF(TAB_HISTORICO_MANUT[[#This Row],[Ajuste - Cod. Despacho]]="",TAB_HISTORICO_MANUT[[#This Row],[Descricao Despacho]],TAB_HISTORICO_MANUT[[#This Row],[Ajuste - Cod. Despacho]])) | Q14: =IF(TAB_HISTORICO_MANUT[[#This Row],[CONT. OCOR.]]="","",IF(TAB_HISTORICO_MANUT[[#This Row],[AJUSTE - BUILD UP]]<>"",TAB_HISTORICO_MANUT[[#This Row],[AJUSTE - BUILD UP]],IF(TAB_HISTORICO_MANUT[[#This Row],[Descricao Despacho]]=LISTAS_APOIO!$I$5,LISTAS_APOIO!$B$3,IF(OR(TAB_HISTORICO_MANUT[[#This Row],[Descricao Despacho]]=LISTAS_APOIO!$I$3,TAB_HISTORICO_MANUT[[#This Row],[Descricao Despacho]]=LISTAS_APOIO!$I$5),VLOOKUP(TAB_HISTORICO_MANUT[[#This Row],[SISTEMA / PERFIL]],APOIO_EXPURGO_BUILD.UP[[Perfil de perdas]:[Build Up Preventia]],2,0),VLOOKUP(TAB_HISTORICO_MANUT[[#This Row],[SISTEMA / PERFIL]],APOIO_EXPURGO_BUILD.UP[[Perfil de perdas]:[Build Up Preventia]],3,0))))) | R14: =IF($Q14="","",(TAB_HISTORICO_MANUT[[#This Row],[Hora Final]]-TAB_HISTORICO_MANUT[[#This Row],[Hora Inicio]])*24) | S14: =IF(TAB_HISTORICO_MANUT[[#This Row],[Tipo]]<>"Mãe","",IF(TAB_HISTORICO_MANUT[[#This Row],[AJUSTE - EXPURGO (S/N)]]<>"",TAB_HISTORICO_MANUT[[#This Row],[AJUSTE - EXPURGO (S/N)]],IF(TAB_HISTORICO_MANUT[[#This Row],[Descricao Despacho]]=LISTAS_APOIO!$I$5,"SIM",IF(ISERROR(VLOOKUP(TAB_HISTORICO_MANUT[[#This Row],[Descricao Manutencao]],EXPURGO_FILHAS[EXPURGO - FILHAS],1,0)),(_xlfn.XLOOKUP(TAB_HISTORICO_MANUT[[#This Row],[SISTEMA / PERFIL]],APOIO_EXPURGO_BUILD.UP[Perfil de perdas],APOIO_EXPURGO_BUILD.UP[Expurgo],"ADICIONAR CÓDIGO",0,1)),"SIM")))) | T14: =IF(AND(TAB_HISTORICO_MANUT[[#This Row],[EXPURGO Mãe]]="SIM",TAB_HISTORICO_MANUT[[#This Row],[Tipo]]="MÃE"),"EXP.MAE",IF(TAB_HISTORICO_MANUT[[#This Row],[EXPURGO Mãe]]="NÃO","NÃO EXP.MAE",T13)) -> NÃO EXP.MAE | U14: =IF(TAB_HISTORICO_MANUT[[#This Row],[CHECK. EXP. MÃE]]="EXP.MAE","NÃO",IF(TAB_HISTORICO_MANUT[[#This Row],[Tipo]]="Filha",IF(TAB_HISTORICO_MANUT[[#This Row],[AJUSTE - EXPURGO (S/N)]]="",(IF(ISERROR(VLOOKUP(TAB_HISTORICO_MANUT[[#This Row],[Descricao Manutencao]],EXPURGO_FILHAS[EXPURGO - FILHAS],1,0)),"NÃO","SIM")),TAB_HISTORICO_MANUT[[#This Row],[AJUSTE - EXPURGO (S/N)]]),"NÃO")) -> SIM | V14: =IF(TAB_HISTORICO_MANUT[[#This Row],[EXPURGO Filhas]]="SIM",MAX(TAB_HISTORICO_MANUT[[#This Row],[Hora Final]]-TAB_HISTORICO_MANUT[[#This Row],[Hora Inicio]],0),0) -> 0.056702581 | W14: =IF(AND((TAB_HISTORICO_MANUT[[#This Row],[DURAÇÃO - PRODUTO MANUAL]]+TAB_HISTORICO_MANUT[[#This Row],[DURAÇÃO - CARTA MANUAL]])=0,OR(TAB_HISTORICO_MANUT[[#This Row],[PRODUTO]]="SIM",TAB_HISTORICO_MANUT[[#This Row],[CARTA]]="SIM")),TAB_HISTORICO_MANUT[[#This Row],[Duração Ocorrencia]],TAB_HISTORICO_MANUT[[#This Row],[DURAÇÃO - PRODUTO MANUAL]]+TAB_HISTORICO_MANUT[[#This Row],[DURAÇÃO - CARTA MANUAL]]) -> 0 | X14: =IF(AND(TAB_HISTORICO_MANUT[[#This Row],[COMPONENTE]]="SIM",TAB_HISTORICO_MANUT[[#This Row],[DURAÇÃO - COMP. MANUAL]]=""),TAB_HISTORICO_MANUT[[#This Row],[Duração Ocorrencia]],TAB_HISTORICO_MANUT[[#This Row],[DURAÇÃO - COMP. MANUAL]]) -> 0 | Y14: 46028.782 | Z14: 46028.839 | AA14: CA1014KS101 | AB14: 202600085645 | AC14: 9010 | AD14: HMC - Hora de Manutenção Corretiva | AE14: HMC - EXEC BORRACHARIA | AF14: Filha | AG14: =IF(TAB_HISTORICO_MANUT[[#This Row],[Hora Inicio]]="","",MONTH(TAB_HISTORICO_MANUT[[#This Row],[Hora Inicio]])) -> 1 | AH14: BAIXA PRESSÃO DE AR DO PNEU - 202600085645 - REALIZADO CALIBRAGEM DO PNEU TRASEIRO DIREITO EXTERNO MT: 81036838 | AI14: LOCOMOCAO | AJ14: RODA TDE | AK14: PNEU | AL14: BAIXA PRESSAO | AM14: CALIBRAR | AN14: Borracharia | AO14: Locomocao - Roda Tde | AP14: Pneu-Pressao
